Workbook

Sheet Report
V1: Form No: | X1: 100-UTFORM-010 rev 1.3
V2: Report No:
V3: Date:
V4: Page: | Y4: of
V5: Job #:
A6: Project Information
A7: Customer
A8: Address
A9: Contractor
A10: Item Description
A11: Exam Code/Specification | J11: Acceptance Standard | S11: Procedure | Y11: REV
A12: Equipment & Parameters
A13: Testing Instrument | E13: Probe and Wedge | F13: Probe 1 (90°) | G13: Probe 2 (270°) | H13: Probe 3 (0°) | I13: Probe 4 (Trans) | J13: Group Settings | L13: Group 1 | N13: Group 2 | P13: Group 3 | Q13: Group 4 (0°) | S13: Group 5 (Trans) | U13: Material Information | W13: Cal. Std. S/N | Y13: Item Inspected
A16: Manufacturer | E16: Make | J16: Scan | U16: Block Type
A17: Model | E17: Model | J17: Wave Mode | U17: Material
A18: S/N | E18: Frequency | J18: Angle(s) | U18: Velocity Shear
A19: Cal. Due date | E19: Cable /type | J19: Ele start/stop | U19: Velocity L-Wave
A20: Module Model | E20: Cable / length | J20: Angle Increment | U20: Diameter
A21: Module S/N | E21: Probe S/N | J21: Ele per VPA / VPA Index | U21: Sch/Nom. Thk
A22: Cal. Due Date | E22: Wedge Mat'l | J22: Focal Plane | U22: Temp (°F)
A23: Software version | E23: Wedge Model | J23: Focal Distance | U23: Surface condition
A24: Scanner type | E24: Wedge Ref. Angle | J24: Time base, start /stop (60°) | U24: Exam surface (I.D/OD)
A25: Scanner make/model | E25: Wedge Dia. | J25: Pulser Voltage | U25: Couplant
A26: Analysis software | E26: Wedge Curve Type | J26: Points Quantity | U26: Bevel geometry
A27: Analysis software version | E27: Probe check | J27: Smoothing
E28: Relevant Group | J28: Filter settings | U28: Block Type
E29: Add Relevant Group | J29: Amplitude Range | U29: Block S/N
E30: Add Relevant Group | J30: Reference dB | U30: Material
J31: Transfer dB | U31: Velocity Shear
J32: Scanning dB | U32: Velocity L-Wave
A33: Encoder Cal. (steps/in) | E33: CALIBRATION | F33: Cal. Time | G33: Amp | H33: Sweep | I33: Probe Pos. | J33: TCG Parameters | U33: Diameter
A34: Scan Res. (in) | E34: Initial | J34: TCG Block Used | P34: Ref Block Used | U34: Sch/Nom. Thk
A35: Speed (in/sec) | E35: Cal. Check | J35: Reflector Type | U35: Temp (°F)
E36: Cal. Check | J36: Distance | U36: Surface condition
E37: Cal. Out | J37: Amplitude | U37: Exam surface (I.D/OD)
A38: Examination Details and Results
A39: Location | K39: Flaw Details
A40: Weld ID | C40: Welder ID | D40: C/L Offset (in) | E40: Weld Width (in) | F40: Scan Start | G40: Scan Direction | H40: Probe 1 Location | I40: Probe 1 Thickness | J40: Probe 2 Thickness | K40: Circ Start (in) | L40: Length (in) | M40: Axial Pos. (in) | N40: Depth (in) | O40: Height (in) | P40: % Amp | Q40: Type | S40: Accept / Reject | U40: Notes / Comments / Restricted Areas
A53: Notes:
A55: Technician: | F55: Signature | O55: Certification | T55: Customer Acceptance
...

Sheet Indication
V1: Form No: | X1: =IF(Report!X1="","",Report!X1) -> 100-UTFORM-010 rev 1.3
V2: Report No: | X2: =IF(Report!X2="","",Report!X2)
V3: Date: | X3: =IF(Report!X3="","",Report!X3)
V4: Page: | Y4: of
V5: Job #: | X5: =IF(Report!X5="","",Report!X5)
A6: Project Information
A7: Customer | C7: =IF(Report!C7="","",Report!C7)
A8: Address | C8: =IF(Report!C8="","",Report!C8)
A9: Contractor | C9: =IF(Report!C9="","",Report!C9)
A10: Item Description | C10: =IF(Report!C10="","",Report!C10)
A11: Exam Standard | C11: =IF(Report!C11="","",Report!C11) | J11: Acceptance Standard | L11: =IF(Report!L11="","",Report!L11) | S11: Procedure | U11: =IF(Report!U11="","",Report!U11) | Y11: REV | Z11: =IF(Report!Z11="","",Report!Z11)
A12: Insert Picture of Indication
A57: Weld Number | J57: Indication Number
A60: Notes:
A64: Technician: | C64: =IF(Report!C55="","",Report!C55) | I64: Certification | M64: =IF(Report!R55="","",Report!R55)
A66: The examination results included in this report are an interpretation of the testing data and not a guarantee of equipment, part, or component condition.

Sheet Continuation
V1: Form No: | X1: =IF(Report!X1="","",Report!X1) -> 100-UTFORM-010 rev 1.3
V2: Report No: | X2: =IF(Report!X2="","",Report!X2)
V3: Date: | X3: =IF(Report!X3="","",Report!X3)
V4: Page: | Y4: of
V5: Job #: | X5: =IF(Report!X5="","",Report!X5)
A6: Project Information
A7: Customer | C7: =IF(Report!C7="","",Report!C7)
A8: Address | C8: =IF(Report!C8="","",Report!C8)
A9: Contractor | C9: =IF(Report!C9="","",Report!C9)
A10: Item Description | C10: =IF(Report!C10="","",Report!C10)
A11: Exam Standard | C11: =IF(Report!C11="","",Report!C11) | J11: Acceptance Standard | L11: =IF(Report!L11="","",Report!L11) | S11: Procedure | U11: =IF(Report!U11="","",Report!U11) | Y11: REV | Z11: =IF(Report!Z11="","",Report!Z11)
A12: Examination Details and Results
A13: Location | K13: Flaw Details
A14: Weld ID | C14: Welder ID | D14: C/L Offset (in) | E14: Weld Width (in) | F14: Scan Start | G14: Scan Direction | H14: Probe 1 Location | I14: Probe 1 Thickness | J14: Probe 2 Thickness | K14: Circ Start (in) | L14: Length (in) | M14: Axial Pos. (in) | N14: Depth (in) | O14: Height (in) | P14: % Amp | Q14: Type | S14: Accept | T14: Reject | U14: Comments
A48: Notes:
A52: Technician: | C52: =IF(Report!C55="","",Report!C55) | H52: Certification | K52: =IF(Report!R55="","",Report!R55)
A54: The examination results included in this report are an interpretation of the testing data and not a guarantee of equipment, part, or component condition.

Sheet Scan Plan
V1: Form No: | X1: =IF(Report!X1="","",Report!X1) -> 100-UTFORM-010 rev 1.3
V2: Report No: | X2: =IF(Report!X2="","",Report!X2)
V3: Date: | X3: =IF(Report!X3="","",Report!X3)
V4: Page: | Y4: of
V5: Job #: | X5: =IF(Report!X5="","",Report!X5)
A6: Project Information
A7: Customer | C7: =IF(Report!C7="","",Report!C7)
A8: Address | C8: =IF(Report!C8="","",Report!C8)
A9: Contractor | C9: =IF(Report!C9="","",Report!C9)
A10: Item Description | C10: =IF(Report!C10="","",Report!C10)
A11: Exam Standard | C11: =IF(Report!C11="","",Report!C11) | J11: Acceptance Standard | L11: =IF(Report!L11="","",Report!L11) | S11: Procedure | U11: =IF(Report!U11="","",Report!U11) | Y11: REV | Z11: =IF(Report!Z11="","",Report!Z11)
A57: Scan Plan | J57: Pipe Size
A60: Notes:
A64: Technician: | C64: =IF(Report!C55="","",Report!C55) | I64: Certification | M64: =IF(Report!R55="","",Report!R55)
A66: The examination results included in this report are an interpretation of the testing data and not a guarantee of equipment, part, or component condition.
